Workbook

Sheet MASTER_SHEET
A1: OVERALL SUMMARY | B1: Total Revenue | C1: Total Cost | D1: Overall ROAS | E1: Total Profit | F1: Total Conv | G1: Overall CPA | H1: PAUSE Count | I1: SCALE Count
B2: =SUM(P10:P6109) -> 552176.52 | C2: =SUM(O10:O6109) -> 170173.18 | D2: =IFERROR(B2/C2,0) -> 3.2447917 | E2: =B2-C2 -> 382003.34 | F2: =SUM(N10:N6109) -> 9955 | G2: =IFERROR(C2/F2,0) -> 17.094242 | H2: =COUNTIF(X10:X6109,"PAUSE") -> 2546 | I2: =COUNTIF(X10:X6109,"SCALE") -> 3554
A4: Platform | B4: Total Revenue | C4: Total Cost | D4: ROAS | E4: Conversions
A5: Google Ads | B5: =SUMIF($I$10:$I$6109,"Google Ads",$P$10:$P$6109) -> 190827.89 | C5: =SUMIF($I$10:$I$6109,"Google Ads",$O$10:$O$6109) -> 57593.42 | D5: =IFERROR(B5/C5,0) -> 3.3133627 | E5: =SUMIF($I$10:$I$6109,"Google Ads",$N$10:$N$6109) -> 3411
A6: Facebook Ads | B6: =SUMIF($I$10:$I$6109,"Facebook Ads",$P$10:$P$6109) -> 187088.02 | C6: =SUMIF($I$10:$I$6109,"Facebook Ads",$O$10:$O$6109) -> 57083.8 | D6: =IFERROR(B6/C6,0) -> 3.2774276 | E6: =SUMIF($I$10:$I$6109,"Facebook Ads",$N$10:$N$6109) -> 3381
A7: TikTok Ads | B7: =SUMIF($I$10:$I$6109,"TikTok Ads",$P$10:$P$6109) -> 174260.61 | C7: =SUMIF($I$10:$I$6109,"TikTok Ads",$O$10:$O$6109) -> 55495.96 | D7: =IFERROR(B7/C7,0) -> 3.1400594 | E7: =SUMIF($I$10:$I$6109,"TikTok Ads",$N$10:$N$6109) -> 3163
A9: EMAIL | B9: firstname | C9: lastname | D9: city | E9: state | F9: salary | G9: employer | H9: campaign_name | I9: platform | J9: Date | K9: loan_amount.1 | L9: impressions | M9: clicks | N9: conversions | O9: cost | P9: revenue | Q9: ROAS | R9: Profit | S9: ROI% | T9: CTR | U9: CPC | V9: CPA | W9: Conv% | X9: Status | Y9: Loan_Bucket
A10: brodriguez.hojo@yahoo.com | B10: beverly | C10: rodriguez | D10: Wichita Falls | E10: TX | F10: 6369 | G10: na | H10: Campaign_10 | I10: Google Ads | J10: 2024-01-12 | K10: 700 | L10: 707 | M10: 13 | N10: 0 | O10: 8.01 | P10: 0 | Q10: =IFERROR(P10-O10, 0) -> -8.01 | R10: =P10-O10 -> -8.01 | S10: =R10/O10 -> -1 | T10: 1.84 | U10: 0.62 | V10: 0 | W10: =N10/M10 -> 0 | X10: =IF(P10>=4, "SCALE", IF(P10>=2, "MONITOR", IF(P10>=1, "OPTIMISE", "PAUSE"))) -> PAUSE | Y10: =IF(K10<=300,"Low (100-300)", IF(K10<=500,"Mid (301-500)", IF(K10<=750,"High (501-750)", "Premium (751-1000)"))) -> High (501-750)
A11: mickeymousee2@yahoo.com | B11: debra | C11: johnson | D11: Wilson | E11: NC | F11: 1500 | G11: fred hight | H11: Campaign_16 | I11: Google Ads | J11: 2024-01-04 | K11: 800 | L11: 738 | M11: 13 | N11: 0 | O11: 6.34 | P11: 0 | Q11: =IFERROR(P11-O11, 0) -> -6.34 | R11: =P11-O11 -> -6.34 | S11: =R11/O11 -> -1 | T11: 1.76 | U11: 0.49 | V11: 0 | W11: =N11/M11 -> 0 | X11: =IF(P11>=4, "SCALE", IF(P11>=2, "MONITOR", IF(P11>=1, "OPTIMISE", "PAUSE"))) -> PAUSE | Y11: =IF(K11<=300,"Low (100-300)", IF(K11<=500,"Mid (301-500)", IF(K11<=750,"High (501-750)", "Premium (751-1000)"))) -> Premium (751-1000)
A12: elon41@gmail.com | B12: elon | C12: dickey | D12: Daytona Beach | E12: FL | F12: 5000 | G12: mc donalds | H12: Campaign_18 | I12: Google Ads | J12: 2024-01-16 | K12: 800 | L12: 2315 | M12: 39 | N12: 3 | O12: 22.7 | P12: 209.05 | Q12: =IFERROR(P12-O12, 0) -> 186.35 | R12: =P12-O12 -> 186.35 | S12: =R12/O12 -> 8.2092511 | T12: 1.68 | U12: 0.58 | V12: 7.57 | W12: =N12/M12 -> 0.076923077 | X12: =IF(P12>=4, "SCALE", IF(P12>=2, "MONITOR", IF(P12>=1, "OPTIMISE", "PAUSE"))) -> SCALE | Y12: =IF(K12<=300,"Low (100-300)", IF(K12<=500,"Mid (301-500)", IF(K12<=750,"High (501-750)", "Premium (751-1000)"))) -> Premium (751-1000)
A13: ccdmflz@bellsouth.net | B13: charles | C13: wattik | D13: Jonesville | E13: LA | F13: 1500 | G13: security insurance | H13: Campaign_11 | I13: Google Ads | J13: 2024-01-22 | K13: 500 | L13: 1401 | M13: 30 | N13: 0 | O13: 14.98 | P13: 0 | Q13: =IFERROR(P13-O13, 0) -> -14.98 | R13: =P13-O13 -> -14.98 | S13: =R13/O13 -> -1 | T13: 2.14 | U13: 0.5 | V13: 0 | W13: =N13/M13 -> 0 | X13: =IF(P13>=4, "SCALE", IF(P13>=2, "MONITOR", IF(P13>=1, "OPTIMISE", "PAUSE"))) -> PAUSE | Y13: =IF(K13<=300,"Low (100-300)", IF(K13<=500,"Mid (301-500)", IF(K13<=750,"High (501-750)", "Premium (751-1000)"))) -> Mid (301-500)
A14: ashlallemand28@yahoo.com | B14: ashley | C14: lallemand | D14: Canal Winches | E14: OH | F14: 7042 | G14: franklin county | H14: Campaign_5 | I14: Google Ads | J14: 2024-01-09 | K14: 600 | L14: 776 | M14: 30 | N14: 0 | O14: 25.31 | P14: 0 | Q14: =IFERROR(P14-O14, 0) -> -25.31 | R14: =P14-O14 -> -25.31 | S14: =R14/O14 -> -1 | T14: 3.87 | U14: 0.84 | V14: 0 | W14: =N14/M14 -> 0 | X14: =IF(P14>=4, "SCALE", IF(P14>=2, "MONITOR", IF(P14>=1, "OPTIMISE", "PAUSE"))) -> PAUSE | Y14: =IF(K14<=300,"Low (100-300)", IF(K14<=500,"Mid (301-500)", IF(K14<=750,"High (501-750)", "Premium (751-1000)"))) -> High (501-750)
A15: hugocleary@hotmail.com | B15: hugo | C15: cleary | D15: Charlotte | E15: NC | F15: 1284 | G15: mages | H15: Campaign_14 | I15: Google Ads | J15: 2024-01-29 | K15: 300 | L15: 1010 | M15: 19 | N15: 1 | O15: 13.69 | P15: 48.33 | Q15: =IFERROR(P15-O15, 0) -> 34.64 | R15: =P15-O15 -> 34.64 | S15: =R15/O15 -> 2.5303141 | T15: 1.88 | U15: 0.72 | V15: 13.69 | W15: =N15/M15 -> 0.052631579 | X15: =IF(P15>=4, "SCALE", IF(P15>=2, "MONITOR", IF(P15>=1, "OPTIMISE", "PAUSE"))) -> SCALE | Y15: =IF(K15<=300,"Low (100-300)", IF(K15<=500,"Mid (301-500)", IF(K15<=750,"High (501-750)", "Premium (751-1000)"))) -> Low (100-300)
A16: altonwjr@gmail.com | B16: alton | C16: white | D16: Lubbock | E16: TX | F16: 3700 | G16: joe\\'s crab shack | H16: Campaign_8 | I16: Google Ads | J16: 2024-01-05 | K16: 500 | L16: 2482 | M16: 96 | N16: 10 | O16: 57.44 | P16: 698.1 | Q16: =IFERROR(P16-O16, 0) -> 640.66 | R16: =P16-O16 -> 640.66 | S16: =R16/O16 -> 11.153552 | T16: 3.87 | U16: 0.6 | V16: 5.74 | W16: =N16/M16 -> 0.10416667 | X16: =IF(P16>=4, "SCALE", IF(P16>=2, "MONITOR", IF(P16>=1, "OPTIMISE", "PAUSE"))) -> SCALE | Y16: =IF(K16<=300,"Low (100-300)", IF(K16<=500,"Mid (301-500)", IF(K16<=750,"High (501-750)", "Premium (751-1000)"))) -> Mid (301-500)
A17: yolandad.washington@gmail.com | B17: yolando | C17: washington | D17: Florence | E17: SC | F17: 4065 | G17: assurant | H17: Campaign_5 | I17: Google Ads | J17: 2024-01-11 | K17: 200 | L17: 1331 | M17: 27 | N17: 1 | O17: 16.42 | P17: 41.3 | Q17: =IFERROR(P17-O17, 0) -> 24.88 | R17: =P17-O17 -> 24.88 | S17: =R17/O17 -> 1.5152253 | T17: 2.03 | U17: 0.61 | V17: 16.42 | W17: =N17/M17 -> 0.037037037 | X17: =IF(P17>=4, "SCALE", IF(P17>=2, "MONITOR", IF(P17>=1, "OPTIMISE", "PAUSE"))) -> SCALE | Y17: =IF(K17<=300,"Low (100-300)", IF(K17<=500,"Mid (301-500)", IF(K17<=750,"High (501-750)", "Premium (751-1000)"))) -> Low (100-300)
A18: amber6329@gmail.com | B18: amber | C18: jones | D18: Cumberland | E18: VA | F18: 3100 | G18: wells fargo | H18: Campaign_1 | I18: Google Ads | J18: 2024-01-26 | K18: 1000 | L18: 1908 | M18: 63 | N18: 6 | O18: 32.2 | P18: 324.79 | Q18: =IFERROR(P18-O18, 0) -> 292.59 | R18: =P18-O18 -> 292.59 | S18: =R18/O18 -> 9.086646 | T18: 3.3 | U18: 0.51 | V18: 5.37 | W18: =N18/M18 -> 0.095238095 | X18: =IF(P18>=4, "SCALE", IF(P18>=2, "MONITOR", IF(P18>=1, "OPTIMISE", "PAUSE"))) -> SCALE | Y18: =IF(K18<=300,"Low (100-300)", IF(K18<=500,"Mid (301-500)", IF(K18<=750,"High (501-750)", "Premium (751-1000)"))) -> Premium (751-1000)
A19: minnie_82_00@yahoo.com | B19: angela | C19: hairston | D19: Fieldale | E19: VA | F19: 5282 | G19: memorial hospital | H19: Campaign_13 | I19: Google Ads | J19: 2024-01-30 | K19: 500 | L19: 937 | M19: 24 | N19: 1 | O19: 20.4 | P19: 42.54 | Q19: =IFERROR(P19-O19, 0) -> 22.14 | R19: =P19-O19 -> 22.14 | S19: =R19/O19 -> 1.0852941 | T19: 2.56 | U19: 0.85 | V19: 20.4 | W19: =N19/M19 -> 0.041666667 | X19: =IF(P19>=4, "SCALE", IF(P19>=2, "MONITOR", IF(P19>=1, "OPTIMISE", "PAUSE"))) -> SCALE | Y19: =IF(K19<=300,"Low (100-300)", IF(K19<=500,"Mid (301-500)", IF(K19<=750,"High (501-750)", "Premium (751-1000)"))) -> Mid (301-500)
A20: lovingiimerii@gmail.com | B20: yasmeen | C20: roddy | D20: Las Vegas | E20: NV | F20: 2750 | G20: nba raw sports | H20: Campaign_3 | I20: Google Ads | J20: 2024-01-16 | K20: 200 | L20: 808 | M20: 17 | N20: 0 | O20: 10.9 | P20: 0 | Q20: =IFERROR(P20-O20, 0) -> -10.9 | R20: =P20-O20 -> -10.9 | S20: =R20/O20 -> -1 | T20: 2.1 | U20: 0.64 | V20: 0 | W20: =N20/M20 -> 0 | X20: =IF(P20>=4, "SCALE", IF(P20>=2, "MONITOR", IF(P20>=1, "OPTIMISE", "PAUSE"))) -> PAUSE | Y20: =IF(K20<=300,"Low (100-300)", IF(K20<=500,"Mid (301-500)", IF(K20<=750,"High (501-750)", "Premium (751-1000)"))) -> Low (100-300)
A21: justinhilton81@gmail.com | B21: justin | C21: hilton | D21: Christiansbur | E21: VA | F21: 1500 | G21: energy management services | H21: Campaign_18 | I21: Google Ads | J21: 2024-01-11 | K21: 300 | L21: 2006 | M21: 48 | N21: 0 | O21: 23.39 | P21: 0 | Q21: =IFERROR(P21-O21, 0) -> -23.39 | R21: =P21-O21 -> -23.39 | S21: =R21/O21 -> -1 | T21: 2.39 | U21: 0.49 | V21: 0 | W21: =N21/M21 -> 0 | X21: =IF(P21>=4, "SCALE", IF(P21>=2, "MONITOR", IF(P21>=1, "OPTIMISE", "PAUSE"))) -> PAUSE | Y21: =IF(K21<=300,"Low (100-300)", IF(K21<=500,"Mid (301-500)", IF(K21<=750,"High (501-750)", "Premium (751-1000)"))) -> Low (100-300)
... A42: valeriejjohnson@gmail.com | B42: valerie | C42: johnson | D42: South Holland | E42: IL | F42: 4500 | G42: levitz furniture | H42: Campaign_8 | I42: Google Ads | J42: 2024-01-29 | K42: 100 | L42: 1159 | M42: 24 | N42: 2 | O42: 13.03 | P42: 133.86 | Q42: =IFERROR(P42-O42, 0) -> 120.83 | R42: =P42-O42 -> 120.83 | S42: =R42/O42 -> 9.2732157 | T42: 2.07 | U42: 0.54 | V42: 6.52 | W42: =N42/M42 -> 0.083333333 | X42: =IF(P42>=4, "SCALE", IF(P42>=2, "MONITOR", IF(P42>=1, "OPTIMISE", "PAUSE"))) -> SCALE | Y42: =IF(K42<=300,"Low (100-300)", IF(K42<=500,"Mid (301-500)", IF(K42<=750,"High (501-750)", "Premium (751-1000)"))) -> Low (100-300)
A43: samkrb101@gmail.com | B43: sam | C43: kirby | D43: Goreville | E43: IL | F43: 5417 | G43: 0 | H43: Campaign_13 | I43: Google Ads | J43: 2024-01-24 | K43: 400 | L43: 788 | M43: 17 | N43: 0 | O43: 13.99 | P43: 0 | Q43: =IFERROR(P43-O43, 0) -> -13.99 | R43: =P43-O43 -> -13.99 | S43: =R43/O43 -> -1 | T43: 2.16 | U43: 0.82 | V43: 0 | W43: =N43/M43 -> 0 | X43: =IF(P43>=4, "SCALE", IF(P43>=2, "MONITOR", IF(P43>=1, "OPTIMISE", "PAUSE"))) -> PAUSE | Y43: =IF(K43<=300,"Low (100-300)", IF(K43<=500,"Mid (301-500)", IF(K43<=750,"High (501-750)", "Premium (751-1000)"))) -> Mid (301-500)
A44: januaryh272@yahoo.com | B44: january | C44: harris | D44: Saint Louis | E44: MO | F44: 1300 | G44: gma paralegal services;llc | H44: Campaign_6 | I44: Google Ads | J44: 2024-01-11 | K44: 400 | L44: 1941 | M44: 85 | N44: 3 | O44: 40.6 | P44: 136.75 | Q44: =IFERROR(P44-O44, 0) -> 96.15 | R44: =P44-O44 -> 96.15 | S44: =R44/O44 -> 2.3682266 | T44: 4.38 | U44: 0.48 | V44: 13.53 | W44: =N44/M44 -> 0.035294118 | X44: =IF(P44>=4, "SCALE", IF(P44>=2, "MONITOR", IF(P44>=1, "OPTIMISE", "PAUSE"))) -> SCALE | Y44: =IF(K44<=300,"Low (100-300)", IF(K44<=500,"Mid (301-500)", IF(K44<=750,"High (501-750)", "Premium (751-1000)"))) -> Mid (301-500)
A45: valeriewalden@yahoo.com | B45: valerie | C45: walden | D45: Beaumont | E45: TX | F45: 1500 | G45: forth & towne | H45: Campaign_16 | I45: Google Ads | J45: 2024-01-08 | K45: 700 | L45: 676 | M45: 22 | N45: 1 | O45: 14.77 | P45: 49.55 | Q45: =IFERROR(P45-O45, 0) -> 34.78 | R45: =P45-O45 -> 34.78 | S45: =R45/O45 -> 2.3547732 | T45: 3.25 | U45: 0.67 | V45: 14.77 | W45: =N45/M45 -> 0.045454545 | X45: =IF(P45>=4, "SCALE", IF(P45>=2, "MONITOR", IF(P45>=1, "OPTIMISE", "PAUSE"))) -> SCALE | Y45: =IF(K45<=300,"Low (100-300)", IF(K45<=500,"Mid (301-500)", IF(K45<=750,"High (501-750)", "Premium (751-1000)"))) -> High (501-750)
A46: uearl51@yahoo.com | B46: earl | C46: underwood | D46: Navasota | E46: TX | F46: 2167 | G46: bj trucking | H46: Campaign_4 | I46: Google Ads | J46: 2024-01-13 | K46: 500 | L46: 1268 | M46: 50 | N46: 1 | O46: 34.57 | P46: 50.35 | Q46: =IFERROR(P46-O46, 0) -> 15.78 | R46: =P46-O46 -> 15.78 | S46: =R46/O46 -> 0.45646514 | T46: 3.94 | U46: 0.69 | V46: 34.57 | W46: =N46/M46 -> 0.02 | X46: =IF(P46>=4, "SCALE", IF(P46>=2, "MONITOR", IF(P46>=1, "OPTIMISE", "PAUSE"))) -> SCALE | Y46: =IF(K46<=300,"Low (100-300)", IF(K46<=500,"Mid (301-500)", IF(K46<=750,"High (501-750)", "Premium (751-1000)"))) -> Mid (301-500)
A47: jonesletique@gmail.com | B47: cathy | C47: jones | D47: Houston | E47: TX | F47: 2708 | G47: houstonisd | H47: Campaign_2 | I47: Google Ads | J47: 2024-01-08 | K47: 700 | L47: 541 | M47: 18 | N47: 0 | O47: 11.76 | P47: 0 | Q47: =IFERROR(P47-O47, 0) -> -11.76 | R47: =P47-O47 -> -11.76 | S47: =R47/O47 -> -1 | T47: 3.33 | U47: 0.65 | V47: 0 | W47: =N47/M47 -> 0 | X47: =IF(P47>=4, "SCALE", IF(P47>=2, "MONITOR", IF(P47>=1, "OPTIMISE", "PAUSE"))) -> PAUSE | Y47: =IF(K47<=300,"Low (100-300)", IF(K47<=500,"Mid (301-500)", IF(K47<=750,"High (501-750)", "Premium (751-1000)"))) -> High (501-750)
A48: elmarquez@gmail.com | B48: eloise | C48: marquez | D48: Portland | E48: OR | F48: 3250 | G48: realty depot | H48: Campaign_17 | I48: Google Ads | J48: 2024-01-08 | K48: 100 | L48: 1818 | M48: 67 | N48: 0 | O48: 43.74 | P48: 0 | Q48: =IFERROR(P48-O48, 0) -> -43.74 | R48: =P48-O48 -> -43.74 | S48: =R48/O48 -> -1 | T48: 3.69 | U48: 0.65 | V48: 0 | W48: =N48/M48 -> 0 | X48: =IF(P48>=4, "SCALE", IF(P48>=2, "MONITOR", IF(P48>=1, "OPTIMISE", "PAUSE"))) -> PAUSE | Y48: =IF(K48<=300,"Low (100-300)", IF(K48<=500,"Mid (301-500)", IF(K48<=750,"High (501-750)", "Premium (751-1000)"))) -> Low (100-300)
A49: laboy783@yahoo.com | B49: eliseo | C49: duarte | D49: Dallas | E49: TX | F49: 4100 | G49: bumc | H49: Campaign_20 | I49: Google Ads | J49: 2024-01-28 | K49: 400 | L49: 2032 | M49: 90 | N49: 0 | O49: 74.64 | P49: 0 | Q49: =IFERROR(P49-O49, 0) -> -74.64 | R49: =P49-O49 -> -74.64 | S49: =R49/O49 -> -1 | T49: 4.43 | U49: 0.83 | V49: 0 | W49: =N49/M49 -> 0 | X49: =IF(P49>=4, "SCALE", IF(P49>=2, "MONITOR", IF(P49>=1, "OPTIMISE", "PAUSE"))) -> PAUSE | Y49: =IF(K49<=300,"Low (100-300)", IF(K49<=500,"Mid (301-500)", IF(K49<=750,"High (501-750)", "Premium (751-1000)"))) -> Mid (301-500)
A50: bbluv4u2@yahoo.com | B50: marlin | C50: brown | D50: Concord | E50: NC | F50: 3400 | G50: china spring isd | H50: Campaign_19 | I50: Google Ads | J50: 2024-01-23 | K50: 300 | L50: 2373 | M50: 55 | N50: 0 | O50: 25.61 | P50: 0 | Q50: =IFERROR(P50-O50, 0) -> -25.61 | R50: =P50-O50 -> -25.61 | S50: =R50/O50 -> -1 | T50: 2.32 | U50: 0.47 | V50: 0 | W50: =N50/M50 -> 0 | X50: =IF(P50>=4, "SCALE", IF(P50>=2, "MONITOR", IF(P50>=1, "OPTIMISE", "PAUSE"))) -> PAUSE | Y50: =IF(K50<=300,"Low (100-300)", IF(K50<=500,"Mid (301-500)", IF(K50<=750,"High (501-750)", "Premium (751-1000)"))) -> Low (100-300)
A51: heruone2000@yahoo.com | B51: terrance | C51: merck | D51: Detroit | E51: MI | F51: 2498 | G51: embrenche | H51: Campaign_8 | I51: Google Ads | J51: 2024-01-17 | K51: 1000 | L51: 1148 | M51: 17 | N51: 1 | O51: 8.05 | P51: 70.32 | Q51: =IFERROR(P51-O51, 0) -> 62.27 | R51: =P51-O51 -> 62.27 | S51: =R51/O51 -> 7.7354037 | T51: 1.48 | U51: 0.47 | V51: 8.05 | W51: =N51/M51 -> 0.058823529 | X51: =IF(P51>=4, "SCALE", IF(P51>=2, "MONITOR", IF(P51>=1, "OPTIMISE", "PAUSE"))) -> SCALE | Y51: =IF(K51<=300,"Low (100-300)", IF(K51<=500,"Mid (301-500)", IF(K51<=750,"High (501-750)", "Premium (751-1000)"))) -> Premium (751-1000)
A52: buffanged@yahoo.com | B52: angela | C52: buffington | D52: Nicholasville | E52: KY | F52: 2167 | G52: eden bishop | H52: Campaign_19 | I52: Google Ads | J52: 2024-01-15 | K52: 500 | L52: 2166 | M52: 39 | N52: 3 | O52: 20.6 | P52: 175.07 | Q52: =IFERROR(P52-O52, 0) -> 154.47 | R52: =P52-O52 -> 154.47 | S52: =R52/O52 -> 7.4985437 | T52: 1.8 | U52: 0.53 | V52: 6.87 | W52: =N52/M52 -> 0.076923077 | X52: =IF(P52>=4, "SCALE", IF(P52>=2, "MONITOR", IF(P52>=1, "OPTIMISE", "PAUSE"))) -> SCALE | Y52: =IF(K52<=300,"Low (100-300)", IF(K52<=500,"Mid (301-500)", IF(K52<=750,"High (501-750)", "Premium (751-1000)"))) -> Mid (301-500)
A53: rkarinagarzon@hotmail.com | B53: rosana | C53: lamoglia | D53: Naples | E53: FL | F53: 2000 | G53: pelicanbayfoundation | H53: Campaign_17 | I53: Google Ads | J53: 2024-01-10 | K53: 600 | L53: 1430 | M53: 61 | N53: 2 | O53: 45.15 | P53: 104.72 | Q53: =IFERROR(P53-O53, 0) -> 59.57 | R53: =P53-O53 -> 59.57 | S53: =R53/O53 -> 1.3193798 | T53: 4.27 | U53: 0.74 | V53: 22.58 | W53: =N53/M53 -> 0.032786885 | X53: =IF(P53>=4, "SCALE", IF(P53>=2, "MONITOR", IF(P53>=1, "OPTIMISE", "PAUSE"))) -> SCALE | Y53: =IF(K53<=300,"Low (100-300)", IF(K53<=500,"Mid (301-500)", IF(K53<=750,"High (501-750)", "Premium (751-1000)"))) -> High (501-750)
A54: ortizana85@gmail.com | B54: ana | C54: villanueva | D54: Arlington | E54: TX | F54: 3100 | G54: ats | H54: Campaign_11 | I54: Google Ads | J54: 2024-01-14 | K54: 1000 | L54: 2055 | M54: 85 | N54: 0 | O54: 64.77 | P54: 0 | Q54: =IFERROR(P54-O54, 0) -> -64.77 | R54: =P54-O54 -> -64.77 | S54: =R54/O54 -> -1 | T54: 4.14 | U54: 0.76 | V54: 0 | W54: =N54/M54 -> 0 | X54: =IF(P54>=4, "SCALE", IF(P54>=2, "MONITOR", IF(P54>=1, "OPTIMISE", "PAUSE"))) -> PAUSE | Y54: =IF(K54<=300,"Low (100-300)", IF(K54<=500,"Mid (301-500)", IF(K54<=750,"High (501-750)", "Premium (751-1000)"))) -> Premium (751-1000)
A55: revo6419@gmail.com | B55: david | C55: revolinski | D55: Fort Atkinson | E55: WI | F55: 1924 | G55: eaton | H55: Campaign_20 | I55: Google Ads | J55: 2024-01-20 | K55: 400 | L55: 1727 | M55: 26 | N55: 3 | O55: 16.67 | P55: 162.56 | Q55: =IFERROR(P55-O55, 0) -> 145.89 | R55: =P55-O55 -> 145.89 | S55: =R55/O55 -> 8.7516497 | T55: 1.51 | U55: 0.64 | V55: 5.56 | W55: =N55/M55 -> 0.11538462 | X55: =IF(P55>=4, "SCALE", IF(P55>=2, "MONITOR", IF(P55>=1, "OPTIMISE", "PAUSE"))) -> SCALE | Y55: =IF(K55<=300,"Low (100-300)", IF(K55<=500,"Mid (301-500)", IF(K55<=750,"High (501-750)", "Premium (751-1000)"))) -> Mid (301-500)
... A69: dtfrison05@yahoo.com | B69: dawntesha | C69: frison | D69: Tolleson | E69: AZ | F69: 2708 | G69: wells fargo | H69: Campaign_10 | I69: Google Ads | J69: 2024-01-28 | K69: 700 | L69: 850 | M69: 22 | N69: 0 | O69: 15.66 | P69: 0 | Q69: =IFERROR(P69-O69, 0) -> -15.66 | R69: =P69-O69 -> -15.66 | S69: =R69/O69 -> -1 | T69: 2.59 | U69: 0.71 | V69: 0 | W69: =N69/M69 -> 0 | X69: =IF(P69>=4, "SCALE", IF(P69>=2, "MONITOR", IF(P69>=1, "OPTIMISE", "PAUSE"))) -> PAUSE | Y69: =IF(K69<=300,"Low (100-300)", IF(K69<=500,"Mid (301-500)", IF(K69<=750,"High (501-750)", "Premium (751-1000)"))) -> High (501-750)
A70: rgililland@live.com | B70: rebekah | C70: gililland | D70: Oklahoma City | E70: OK | F70: 1733 | G70: 0 | H70: Campaign_7 | I70: Google Ads | J70: 2024-01-03 | K70: 400 | L70: 834 | M70: 15 | N70: 0 | O70: 7.46 | P70: 0 | Q70: =IFERROR(P70-O70, 0) -> -7.46 | R70: =P70-O70 -> -7.46 | S70: =R70/O70 -> -1 | T70: 1.8 | U70: 0.5 | V70: 0 | W70: =N70/M70 -> 0 | X70: =IF(P70>=4, "SCALE", IF(P70>=2, "MONITOR", IF(P70>=1, "OPTIMISE", "PAUSE"))) -> PAUSE | Y70: =IF(K70<=300,"Low (100-300)", IF(K70<=500,"Mid (301-500)", IF(K70<=750,"High (501-750)", "Premium (751-1000)"))) -> Mid (301-500)
A71: a30yroldfrog@aol.com | B71: angela | C71: stephens | D71: Lehigh Acres | E71: FL | F71: 2500 | G71: murphy usa | H71: Campaign_13 | I71: Google Ads | J71: 2024-01-28 | K71: 1000 | L71: 648 | M71: 26 | N71: 0 | O71: 16.05 | P71: 0 | Q71: =IFERROR(P71-O71, 0) -> -16.05 | R71: =P71-O71 -> -16.05 | S71: =R71/O71 -> -1 | T71: 4.01 | U71: 0.62 | V71: 0 | W71: =N71/M71 -> 0 | X71: =IF(P71>=4, "SCALE", IF(P71>=2, "MONITOR", IF(P71>=1, "OPTIMISE", "PAUSE"))) -> PAUSE | Y71: =IF(K71<=300,"Low (100-300)", IF(K71<=500,"Mid (301-500)", IF(K71<=750,"High (501-750)", "Premium (751-1000)"))) -> Premium (751-1000)
A72: aydinsmommy1221@live.com | B72: terina | C72: barlow | D72: Chicago | E72: IL | F72: 3900 | G72: tcf national bank illinois | H72: Campaign_13 | I72: Google Ads | J72: 2024-01-06 | K72: 100 | L72: 893 | M72: 15 | N72: 0 | O72: 7.26 | P72: 0 | Q72: =IFERROR(P72-O72, 0) -> -7.26 | R72: =P72-O72 -> -7.26 | S72: =R72/O72 -> -1 | T72: 1.68 | U72: 0.48 | V72: 0 | W72: =N72/M72 -> 0 | X72: =IF(P72>=4, "SCALE", IF(P72>=2, "MONITOR", IF(P72>=1, "OPTIMISE", "PAUSE"))) -> PAUSE | Y72: =IF(K72<=300,"Low (100-300)", IF(K72<=500,"Mid (301-500)", IF(K72<=750,"High (501-750)", "Premium (751-1000)"))) -> Low (100-300)
A73: tiffanylenae04@yahoo.com | B73: tiffany | C73: mock | D73: Ravenna | E73: NE | F73: 2250 | G73: cabelas | H73: Campaign_7 | I73: Google Ads | J73: 2024-01-12 | K73: 800 | L73: 1515 | M73: 33 | N73: 0 | O73: 18.21 | P73: 0 | Q73: =IFERROR(P73-O73, 0) -> -18.21 | R73: =P73-O73 -> -18.21 | S73: =R73/O73 -> -1 | T73: 2.18 | U73: 0.55 | V73: 0 | W73: =N73/M73 -> 0 | X73: =IF(P73>=4, "SCALE", IF(P73>=2, "MONITOR", IF(P73>=1, "OPTIMISE", "PAUSE"))) -> PAUSE | Y73: =IF(K73<=300,"Low (100-300)", IF(K73<=500,"Mid (301-500)", IF(K73<=750,"High (501-750)", "Premium (751-1000)"))) -> Premium (751-1000)
A74: christylnolen@abbey.bac.edu | B74: christy | C74: nolen | D74: Cramerton | E74: NC | F74: 4604 | G74: mcso | H74: Campaign_12 | I74: Google Ads | J74: 2024-01-23 | K74: 800 | L74: 1846 | M74: 41 | N74: 0 | O74: 32.59 | P74: 0 | Q74: =IFERROR(P74-O74, 0) -> -32.59 | R74: =P74-O74 -> -32.59 | S74: =R74/O74 -> -1 | T74: 2.22 | U74: 0.79 | V74: 0 | W74: =N74/M74 -> 0 | X74: =IF(P74>=4, "SCALE", IF(P74>=2, "MONITOR", IF(P74>=1, "OPTIMISE", "PAUSE"))) -> PAUSE | Y74: =IF(K74<=300,"Low (100-300)", IF(K74<=500,"Mid (301-500)", IF(K74<=750,"High (501-750)", "Premium (751-1000)"))) -> Premium (751-1000)
A75: lebpsc09@yahoo.com | B75: pam | C75: coston | D75: Charlotte | E75: NC | F75: 4800 | G75: branch banking and trust compa | H75: Campaign_4 | I75: Google Ads | J75: 2024-01-24 | K75: 100 | L75: 936 | M75: 18 | N75: 0 | O75: 9.31 | P75: 0 | Q75: =IFERROR(P75-O75, 0) -> -9.31 | R75: =P75-O75 -> -9.31 | S75: =R75/O75 -> -1 | T75: 1.92 | U75: 0.52 | V75: 0 | W75: =N75/M75 -> 0 | X75: =IF(P75>=4, "SCALE", IF(P75>=2, "MONITOR", IF(P75>=1, "OPTIMISE", "PAUSE"))) -> PAUSE | Y75: =IF(K75<=300,"Low (100-300)", IF(K75<=500,"Mid (301-500)", IF(K75<=750,"High (501-750)", "Premium (751-1000)"))) -> Low (100-300)
...

Sheet INSIGHTS
A1: PERFORMANCE MARKETING — CAMPAIGN ANALYSIS REPORT
A2: OVERALL SUMMARY
A3: Total Revenue | B3: Total Cost | C3: Total Profit | D3: Overall ROAS | E3: Total Conv. | F3: PAUSE Count | G3: SCALE Count
A4: =SUM(PT_Campaign!B2:B21) -> 552176.52 | B4: =SUM(PT_Campaign!C2:C21) -> 170173.18 | C4: =SUM(PT_Campaign!E2:E21) -> 382003.34 | D4: =IFERROR(A4/B4,0) -> 3.2447917 | E4: =SUM(PT_Campaign!D2:D21) -> 9955 | F4: =COUNTIF(PT_Campaign!J2:J21,"PAUSE") -> 2 | G4: =COUNTIF(PT_Campaign!J2:J21,"SCALE") -> 11
A6: TOP 5 PERFORMING CAMPAIGNS
A7: Rank | B7: Campaign | C7: Revenue | D7: Cost | E7: ROAS | F7: Profit | G7: Conversions | H7: ROI%
A8: 1 | B8: =INDEX(PT_Campaign!$A$2:$A$21,MATCH(LARGE(PT_Campaign!$G$2:$G$21,A8),PT_Campaign!$G$2:$G$21,0)) -> Campaign_1 | C8: =INDEX(PT_Campaign!$B$2:$B$21,MATCH(LARGE(PT_Campaign!$G$2:$G$21,A8),PT_Campaign!$G$2:$G$21,0)) -> 29904.15 | D8: =INDEX(PT_Campaign!$C$2:$C$21,MATCH(LARGE(PT_Campaign!$G$2:$G$21,A8),PT_Campaign!$G$2:$G$21,0)) -> 7960.53 | E8: =IFERROR(C8/D8,0) -> 3.7565526 | F8: =C8-D8 -> 21943.62 | G8: =IFERROR(VLOOKUP(B8,PT_Campaign!$A$2:$I$21,4,0),0) -> 530 | H8: =IFERROR((C8-D8)/D8*100,0) -> 275.65526
A9: 2 | B9: =INDEX(PT_Campaign!$A$2:$A$21,MATCH(LARGE(PT_Campaign!$G$2:$G$21,A9),PT_Campaign!$G$2:$G$21,0)) -> Campaign_8 | C9: =INDEX(PT_Campaign!$B$2:$B$21,MATCH(LARGE(PT_Campaign!$G$2:$G$21,A9),PT_Campaign!$G$2:$G$21,0)) -> 32379.51 | D9: =INDEX(PT_Campaign!$C$2:$C$21,MATCH(LARGE(PT_Campaign!$G$2:$G$21,A9),PT_Campaign!$G$2:$G$21,0)) -> 8866.27 | E9: =IFERROR(C9/D9,0) -> 3.6519878 | F9: =C9-D9 -> 23513.24 | G9: =IFERROR(VLOOKUP(B9,PT_Campaign!$A$2:$I$21,4,0),0) -> 577 | H9: =IFERROR((C9-D9)/D9*100,0) -> 265.19878
A10: 3 | B10: =INDEX(PT_Campaign!$A$2:$A$21,MATCH(LARGE(PT_Campaign!$G$2:$G$21,A10),PT_Campaign!$G$2:$G$21,0)) -> Campaign_6 | C10: =INDEX(PT_Campaign!$B$2:$B$21,MATCH(LARGE(PT_Campaign!$G$2:$G$21,A10),PT_Campaign!$G$2:$G$21,0)) -> 26591.14 | D10: =INDEX(PT_Campaign!$C$2:$C$21,MATCH(LARGE(PT_Campaign!$G$2:$G$21,A10),PT_Campaign!$G$2:$G$21,0)) -> 7475.48 | E10: =IFERROR(C10/D10,0) -> 3.5571147 | F10: =C10-D10 -> 19115.66 | G10: =IFERROR(VLOOKUP(B10,PT_Campaign!$A$2:$I$21,4,0),0) -> 485 | H10: =IFERROR((C10-D10)/D10*100,0) -> 255.71147
A11: 4 | B11: =INDEX(PT_Campaign!$A$2:$A$21,MATCH(LARGE(PT_Campaign!$G$2:$G$21,A11),PT_Campaign!$G$2:$G$21,0)) -> Campaign_17 | C11: =INDEX(PT_Campaign!$B$2:$B$21,MATCH(LARGE(PT_Campaign!$G$2:$G$21,A11),PT_Campaign!$G$2:$G$21,0)) -> 29099.18 | D11: =INDEX(PT_Campaign!$C$2:$C$21,MATCH(LARGE(PT_Campaign!$G$2:$G$21,A11),PT_Campaign!$G$2:$G$21,0)) -> 8198.2 | E11: =IFERROR(C11/D11,0) -> 3.5494596 | F11: =C11-D11 -> 20900.98 | G11: =IFERROR(VLOOKUP(B11,PT_Campaign!$A$2:$I$21,4,0),0) -> 524 | H11: =IFERROR((C11-D11)/D11*100,0) -> 254.94596
A12: 5 | B12: =INDEX(PT_Campaign!$A$2:$A$21,MATCH(LARGE(PT_Campaign!$G$2:$G$21,A12),PT_Campaign!$G$2:$G$21,0)) -> Campaign_3 | C12: =INDEX(PT_Campaign!$B$2:$B$21,MATCH(LARGE(PT_Campaign!$G$2:$G$21,A12),PT_Campaign!$G$2:$G$21,0)) -> 28563.44 | D12: =INDEX(PT_Campaign!$C$2:$C$21,MATCH(LARGE(PT_Campaign!$G$2:$G$21,A12),PT_Campaign!$G$2:$G$21,0)) -> 8114.7 | E12: =IFERROR(C12/D12,0) -> 3.5199625 | F12: =C12-D12 -> 20448.74 | G12: =IFERROR(VLOOKUP(B12,PT_Campaign!$A$2:$I$21,4,0),0) -> 513 | H12: =IFERROR((C12-D12)/D12*100,0) -> 251.99625
A14: WORST 5 CAMPAIGNS — PAUSE IMMEDIATELY
A15: Rank | B15: Campaign | C15: Revenue | D15: Cost | E15: ROAS | F15: Profit | G15: Conversions | H15: ROI%
A16: 1 | B16: =INDEX(PT_Campaign!$A$2:$A$21,MATCH(SMALL(PT_Campaign!$G$2:$G$21,A16),PT_Campaign!$G$2:$G$21,0)) -> Campaign_20 | C16: =INDEX(PT_Campaign!$B$2:$B$21,MATCH(SMALL(PT_Campaign!$G$2:$G$21,A16),PT_Campaign!$G$2:$G$21,0)) -> 22153.03 | D16: =INDEX(PT_Campaign!$C$2:$C$21,MATCH(SMALL(PT_Campaign!$G$2:$G$21,A16),PT_Campaign!$G$2:$G$21,0)) -> 8651.58 | E16: =IFERROR(C16/D16,0) -> 2.5605762 | F16: =C16-D16 -> 13501.45 | G16: =IFERROR(VLOOKUP(B16,PT_Campaign!$A$2:$I$21,4,0),0) -> 397 | H16: =IFERROR((C16-D16)/D16*100,0) -> 156.05762
A17: 2 | B17: =INDEX(PT_Campaign!$A$2:$A$21,MATCH(SMALL(PT_Campaign!$G$2:$G$21,A17),PT_Campaign!$G$2:$G$21,0)) -> Campaign_14 | C17: =INDEX(PT_Campaign!$B$2:$B$21,MATCH(SMALL(PT_Campaign!$G$2:$G$21,A17),PT_Campaign!$G$2:$G$21,0)) -> 20658.27 | D17: =INDEX(PT_Campaign!$C$2:$C$21,MATCH(SMALL(PT_Campaign!$G$2:$G$21,A17),PT_Campaign!$G$2:$G$21,0)) -> 7544.56 | E17: =IFERROR(C17/D17,0) -> 2.7381676 | F17: =C17-D17 -> 13113.71 | G17: =IFERROR(VLOOKUP(B17,PT_Campaign!$A$2:$I$21,4,0),0) -> 370 | H17: =IFERROR((C17-D17)/D17*100,0) -> 173.81676
A18: 3 | B18: =INDEX(PT_Campaign!$A$2:$A$21,MATCH(SMALL(PT_Campaign!$G$2:$G$21,A18),PT_Campaign!$G$2:$G$21,0)) -> Campaign_7 | C18: =INDEX(PT_Campaign!$B$2:$B$21,MATCH(SMALL(PT_Campaign!$G$2:$G$21,A18),PT_Campaign!$G$2:$G$21,0)) -> 27744.73 | D18: =INDEX(PT_Campaign!$C$2:$C$21,MATCH(SMALL(PT_Campaign!$G$2:$G$21,A18),PT_Campaign!$G$2:$G$21,0)) -> 9128.92 | E18: =IFERROR(C18/D18,0) -> 3.0392127 | F18: =C18-D18 -> 18615.81 | G18: =IFERROR(VLOOKUP(B18,PT_Campaign!$A$2:$I$21,4,0),0) -> 490 | H18: =IFERROR((C18-D18)/D18*100,0) -> 203.92127
A19: 4 | B19: =INDEX(PT_Campaign!$A$2:$A$21,MATCH(SMALL(PT_Campaign!$G$2:$G$21,A19),PT_Campaign!$G$2:$G$21,0)) -> Campaign_10 | C19: =INDEX(PT_Campaign!$B$2:$B$21,MATCH(SMALL(PT_Campaign!$G$2:$G$21,A19),PT_Campaign!$G$2:$G$21,0)) -> 25920.03 | D19: =INDEX(PT_Campaign!$C$2:$C$21,MATCH(SMALL(PT_Campaign!$G$2:$G$21,A19),PT_Campaign!$G$2:$G$21,0)) -> 8454.75 | E19: =IFERROR(C19/D19,0) -> 3.0657358 | F19: =C19-D19 -> 17465.28 | G19: =IFERROR(VLOOKUP(B19,PT_Campaign!$A$2:$I$21,4,0),0) -> 485 | H19: =IFERROR((C19-D19)/D19*100,0) -> 206.57358
A20: 5 | B20: =INDEX(PT_Campaign!$A$2:$A$21,MATCH(SMALL(PT_Campaign!$G$2:$G$21,A20),PT_Campaign!$G$2:$G$21,0)) -> Campaign_11 | C20: =INDEX(PT_Campaign!$B$2:$B$21,MATCH(SMALL(PT_Campaign!$G$2:$G$21,A20),PT_Campaign!$G$2:$G$21,0)) -> 28711.12 | D20: =INDEX(PT_Campaign!$C$2:$C$21,MATCH(SMALL(PT_Campaign!$G$2:$G$21,A20),PT_Campaign!$G$2:$G$21,0)) -> 9293.97 | E20: =IFERROR(C20/D20,0) -> 3.0892202 | F20: =C20-D20 -> 19417.15 | G20: =IFERROR(VLOOKUP(B20,PT_Campaign!$A$2:$I$21,4,0),0) -> 525 | H20: =IFERROR((C20-D20)/D20*100,0) -> 208.92202

Sheet PT_Campaign
A1: Row Labels | B1: Sum of revenue | C1: Sum of cost | D1: Sum of conversions | E1: Sum of Profit | F1: Average of ROAS | G1: ROAS Check | H1: Profit Check | I1: ROI% | J1: Status
A2: Campaign_1 | B2: 29904.15 | C2: 7960.53 | D2: 530 | E2: 21943.62 | F2: 73.1454 | G2: =IFERROR(B2/C2,0) -> 3.7565526 | H2: =B2-C2 -> 21943.62 | I2: =IFERROR((B2-C2)/C2*100,0) -> 275.65526 | J2: =IF(G2>=3.15,"SCALE",IF(G2>=3,"MONITOR",IF(G2>=2.8,"OPTIMISE","PAUSE"))) -> SCALE
A3: Campaign_10 | B3: 25920.03 | C3: 8454.75 | D3: 485 | E3: 17465.28 | F3: 58.024186 | G3: =IFERROR(B3/C3,0) -> 3.0657358 | H3: =B3-C3 -> 17465.28 | I3: =IFERROR((B3-C3)/C3*100,0) -> 206.57358 | J3: =IF(G3>=3.15,"SCALE",IF(G3>=3,"MONITOR",IF(G3>=2.8,"OPTIMISE","PAUSE"))) -> MONITOR
A4: Campaign_11 | B4: 28711.12 | C4: 9293.97 | D4: 525 | E4: 19417.15 | F4: 59.379664 | G4: =IFERROR(B4/C4,0) -> 3.0892202 | H4: =B4-C4 -> 19417.15 | I4: =IFERROR((B4-C4)/C4*100,0) -> 208.92202 | J4: =IF(G4>=3.15,"SCALE",IF(G4>=3,"MONITOR",IF(G4>=2.8,"OPTIMISE","PAUSE"))) -> MONITOR
A5: Campaign_12 | B5: 24986.1 | C5: 8060.01 | D5: 455 | E5: 16926.09 | F5: 56.608997 | G5: =IFERROR(B5/C5,0) -> 3.1000086 | H5: =B5-C5 -> 16926.09 | I5: =IFERROR((B5-C5)/C5*100,0) -> 210.00086 | J5: =IF(G5>=3.15,"SCALE",IF(G5>=3,"MONITOR",IF(G5>=2.8,"OPTIMISE","PAUSE"))) -> MONITOR
A6: Campaign_13 | B6: 26333.13 | C6: 8504.8 | D6: 472 | E6: 17828.33 | F6: 56.959521 | G6: =IFERROR(B6/C6,0) -> 3.0962668 | H6: =B6-C6 -> 17828.33 | I6: =IFERROR((B6-C6)/C6*100,0) -> 209.62668 | J6: =IF(G6>=3.15,"SCALE",IF(G6>=3,"MONITOR",IF(G6>=2.8,"OPTIMISE","PAUSE"))) -> MONITOR
A7: Campaign_14 | B7: 20658.27 | C7: 7544.56 | D7: 370 | E7: 13113.71 | F7: 47.341913 | G7: =IFERROR(B7/C7,0) -> 2.7381676 | H7: =B7-C7 -> 13113.71 | I7: =IFERROR((B7-C7)/C7*100,0) -> 173.81676 | J7: =IF(G7>=3.15,"SCALE",IF(G7>=3,"MONITOR",IF(G7>=2.8,"OPTIMISE","PAUSE"))) -> PAUSE
A8: Campaign_15 | B8: 28813.24 | C8: 8563.09 | D8: 521 | E8: 20250.15 | F8: 65.961401 | G8: =IFERROR(B8/C8,0) -> 3.3648181 | H8: =B8-C8 -> 20250.15 | I8: =IFERROR((B8-C8)/C8*100,0) -> 236.48181 | J8: =IF(G8>=3.15,"SCALE",IF(G8>=3,"MONITOR",IF(G8>=2.8,"OPTIMISE","PAUSE"))) -> SCALE
A9: Campaign_16 | B9: 24653.74 | C9: 7829.39 | D9: 452 | E9: 16824.35 | F9: 59.240669 | G9: =IFERROR(B9/C9,0) -> 3.1488711 | H9: =B9-C9 -> 16824.35 | I9: =IFERROR((B9-C9)/C9*100,0) -> 214.88711 | J9: =IF(G9>=3.15,"SCALE",IF(G9>=3,"MONITOR",IF(G9>=2.8,"OPTIMISE","PAUSE"))) -> MONITOR
A10: Campaign_17 | B10: 29099.18 | C10: 8198.2 | D10: 524 | E10: 20900.98 | F10: 72.072345 | G10: =IFERROR(B10/C10,0) -> 3.5494596 | H10: =B10-C10 -> 20900.98 | I10: =IFERROR((B10-C10)/C10*100,0) -> 254.94596 | J10: =IF(G10>=3.15,"SCALE",IF(G10>=3,"MONITOR",IF(G10>=2.8,"OPTIMISE","PAUSE"))) -> SCALE
A11: Campaign_18 | B11: 29190.48 | C11: 9242.78 | D11: 536 | E11: 19947.7 | F11: 64.140514 | G11: =IFERROR(B11/C11,0) -> 3.1581927 | H11: =B11-C11 -> 19947.7 | I11: =IFERROR((B11-C11)/C11*100,0) -> 215.81927 | J11: =IF(G11>=3.15,"SCALE",IF(G11>=3,"MONITOR",IF(G11>=2.8,"OPTIMISE","PAUSE"))) -> SCALE
A12: Campaign_19 | B12: 27594.02 | C12: 8300.3 | D12: 495 | E12: 19293.72 | F12: 65.181486 | G12: =IFERROR(B12/C12,0) -> 3.3244606 | H12: =B12-C12 -> 19293.72 | I12: =IFERROR((B12-C12)/C12*100,0) -> 232.44606 | J12: =IF(G12>=3.15,"SCALE",IF(G12>=3,"MONITOR",IF(G12>=2.8,"OPTIMISE","PAUSE"))) -> SCALE
A13: Campaign_2 | B13: 30694.36 | C13: 9643.38 | D13: 563 | E13: 21050.98 | F13: 63.406566 | G13: =IFERROR(B13/C13,0) -> 3.1829462 | H13: =B13-C13 -> 21050.98 | I13: =IFERROR((B13-C13)/C13*100,0) -> 218.29462 | J13: =IF(G13>=3.15,"SCALE",IF(G13>=3,"MONITOR",IF(G13>=2.8,"OPTIMISE","PAUSE"))) -> SCALE
... A22: Grand Total | B22: 552176.52 | C22: 170173.18 | D22: 9955 | E22: 382003.34 | F22: 62.623498 | G22: =IFERROR(B22/C22,0) -> 3.2447917 | H22: =B22-C22 -> 382003.34 | I22: =IFERROR((B22-C22)/C22*100,0) -> 224.47917 | J22: =IF(G22>=3.15,"SCALE",IF(G22>=3,"MONITOR",IF(G22>=2.8,"OPTIMISE","PAUSE"))) -> SCALE

Sheet PT_Platform
B2: Row Labels | C2: Sum of revenue | D2: Sum of cost | E2: Sum of conversions | F2: Sum of clicks | G2: Sum of impressions | H2: ROAS | I2: CPA | J2: CTR
B3: Facebook Ads | C3: 187088.02 | D3: 57083.8 | E3: 3381 | F3: 91359 | G3: 3076865 | H3: =IFERROR(C3/D3,0) -> 3.2774276 | I3: =IFERROR(D3/E3,0) -> 16.883703 | J3: =IFERROR(F3/G3,0) -> 0.029692235
B4: Google Ads | C4: 190827.89 | D4: 57593.42 | E4: 3411 | F4: 92036 | G4: 3108035 | H4: =IFERROR(C4/D4,0) -> 3.3133627 | I4: =IFERROR(D4/E4,0) -> 16.884614 | J4: =IFERROR(F4/G4,0) -> 0.029612279
B5: TikTok Ads | C5: 174260.61 | D5: 55495.96 | E5: 3163 | F5: 88503 | G5: 2960522 | H5: =IFERROR(C5/D5,0) -> 3.1400594 | I5: =IFERROR(D5/E5,0) -> 17.545356 | J5: =IFERROR(F5/G5,0) -> 0.02989439
B6: Grand Total | C6: 552176.52 | D6: 170173.18 | E6: 9955 | F6: 271898 | G6: 9145422 | H6: =IFERROR(C6/D6,0) -> 3.2447917 | I6: =IFERROR(D6/E6,0) -> 17.094242 | J6: =IFERROR(F6/G6,0) -> 0.029730503

Sheet PT_LoanAmt
B2: Row Labels | C2: Sum of revenue | D2: Sum of cost | E2: Sum of Profit | F2: Sum of conversions | G2: ROAS | H2: ROI% | I2: CPA | J2: Best Segment
B3: Premium (751-1000) | C3: 122456.25 | D3: 37608.33 | E3: 84847.92 | F3: 2213 | G3: =IFERROR(C3/D3,0) -> 3.2560938 | H3: =IFERROR((C3-D3)/D3*100,0) -> 225.60938 | I3: =IFERROR(D3/F3,0) -> 16.994275 | J3: =IF(G3>=3.25,"Target This","Review") -> Target This
B4: Mid (301-500) | C4: 121719.36 | D4: 37678.99 | E4: 84040.37 | F4: 2207 | G4: =IFERROR(C4/D4,0) -> 3.2304305 | H4: =IFERROR((C4-D4)/D4*100,0) -> 223.04305 | I4: =IFERROR(D4/F4,0) -> 17.072492 | J4: =IF(G4>=3.25,"Target This","Review") -> Review
B5: Low (100-300) | C5: 184027.95 | D5: 56958.48 | E5: 127069.47 | F5: 3304 | G5: =IFERROR(C5/D5,0) -> 3.230914 | H5: =IFERROR((C5-D5)/D5*100,0) -> 223.0914 | I5: =IFERROR(D5/F5,0) -> 17.239249 | J5: =IF(G5>=3.25,"Target This","Review") -> Review
B6: High (501-750) | C6: 123972.96 | D6: 37927.38 | E6: 86045.58 | F6: 2231 | G6: =IFERROR(C6/D6,0) -> 3.268693 | H6: =IFERROR((C6-D6)/D6*100,0) -> 226.8693 | I6: =IFERROR(D6/F6,0) -> 17.00017 | J6: =IF(G6>=3.25,"Target This","Review") -> Target This
B7: Grand Total | C7: 552176.52 | D7: 170173.18 | E7: 382003.34 | F7: 9955 | G7: =IFERROR(C7/D7,0) -> 3.2447917 | H7: =IFERROR((C7-D7)/D7*100,0) -> 224.47917 | I7: =IFERROR(D7/F7,0) -> 17.094242 | J7: =IF(G7>=3.25,"Target This","Review") -> Review

Sheet raw_google 
A1: EMAIL | B1: firstname | C1: lastname | D1: city | E1: state | F1: employer | G1: campaign_name | H1: platform | I1: Date | J1: loan_amount.1 | K1: impressions | L1: clicks | M1: conversions | N1: cost | O1: revenue | P1: CTR | Q1: CPC | R1: CPA | S1: salary
A2: brodriguez.hojo@yahoo.com | B2: beverly | C2: rodriguez | D2: Wichita Falls | E2: TX | F2: na | G2: Campaign_10 | H2: Google Ads | I2: 2024-01-12 | J2: 700 | K2: 707 | L2: 13 | M2: 0 | N2: 8.01 | O2: 0 | P2: 1.84 | Q2: 0.62 | R2: 0 | S2: 6369
A3: mickeymousee2@yahoo.com | B3: debra | C3: johnson | D3: Wilson | E3: NC | F3: fred hight | G3: Campaign_16 | H3: Google Ads | I3: 2024-01-04 | J3: 800 | K3: 738 | L3: 13 | M3: 0 | N3: 6.34 | O3: 0 | P3: 1.76 | Q3: 0.49 | R3: 0 | S3: 1500
A4: elon41@gmail.com | B4: elon | C4: dickey | D4: Daytona Beach | E4: FL | F4: mc donalds | G4: Campaign_18 | H4: Google Ads | I4: 2024-01-16 | J4: 800 | K4: 2315 | L4: 39 | M4: 3 | N4: 22.7 | O4: 209.05 | P4: 1.68 | Q4: 0.58 | R4: 7.57 | S4: 5000
A5: ccdmflz@bellsouth.net | B5: charles | C5: wattik | D5: Jonesville | E5: LA | F5: security insurance | G5: Campaign_11 | H5: Google Ads | I5: 2024-01-22 | J5: 500 | K5: 1401 | L5: 30 | M5: 0 | N5: 14.98 | O5: 0 | P5: 2.14 | Q5: 0.5 | R5: 0 | S5: 1500
A6: ashlallemand28@yahoo.com | B6: ashley | C6: lallemand | D6: Canal Winches | E6: OH | F6: franklin county | G6: Campaign_5 | H6: Google Ads | I6: 2024-01-09 | J6: 600 | K6: 776 | L6: 30 | M6: 0 | N6: 25.31 | O6: 0 | P6: 3.87 | Q6: 0.84 | R6: 0 | S6: 7042
A7: hugocleary@hotmail.com | B7: hugo | C7: cleary | D7: Charlotte | E7: NC | F7: mages | G7: Campaign_14 | H7: Google Ads | I7: 2024-01-29 | J7: 300 | K7: 1010 | L7: 19 | M7: 1 | N7: 13.69 | O7: 48.33 | P7: 1.88 | Q7: 0.72 | R7: 13.69 | S7: 1284
A8: altonwjr@gmail.com | B8: alton | C8: white | D8: Lubbock | E8: TX | F8: joe\\'s crab shack | G8: Campaign_8 | H8: Google Ads | I8: 2024-01-05 | J8: 500 | K8: 2482 | L8: 96 | M8: 10 | N8: 57.44 | O8: 698.1 | P8: 3.87 | Q8: 0.6 | R8: 5.74 | S8: 3700
A9: yolandad.washington@gmail.com | B9: yolando | C9: washington | D9: Florence | E9: SC | F9: assurant | G9: Campaign_5 | H9: Google Ads | I9: 2024-01-11 | J9: 200 | K9: 1331 | L9: 27 | M9: 1 | N9: 16.42 | O9: 41.3 | P9: 2.03 | Q9: 0.61 | R9: 16.42 | S9: 4065
A10: amber6329@gmail.com | B10: amber | C10: jones | D10: Cumberland | E10: VA | F10: wells fargo | G10: Campaign_1 | H10: Google Ads | I10: 2024-01-26 | J10: 1000 | K10: 1908 | L10: 63 | M10: 6 | N10: 32.2 | O10: 324.79 | P10: 3.3 | Q10: 0.51 | R10: 5.37 | S10: 3100
A11: minnie_82_00@yahoo.com | B11: angela | C11: hairston | D11: Fieldale | E11: VA | F11: memorial hospital | G11: Campaign_13 | H11: Google Ads | I11: 2024-01-30 | J11: 500 | K11: 937 | L11: 24 | M11: 1 | N11: 20.4 | O11: 42.54 | P11: 2.56 | Q11: 0.85 | R11: 20.4 | S11: 5282
A12: lovingiimerii@gmail.com | B12: yasmeen | C12: roddy | D12: Las Vegas | E12: NV | F12: nba raw sports | G12: Campaign_3 | H12: Google Ads | I12: 2024-01-16 | J12: 200 | K12: 808 | L12: 17 | M12: 0 | N12: 10.9 | O12: 0 | P12: 2.1 | Q12: 0.64 | R12: 0 | S12: 2750
A13: justinhilton81@gmail.com | B13: justin | C13: hilton | D13: Christiansbur | E13: VA | F13: energy management services | G13: Campaign_18 | H13: Google Ads | I13: 2024-01-11 | J13: 300 | K13: 2006 | L13: 48 | M13: 0 | N13: 23.39 | O13: 0 | P13: 2.39 | Q13: 0.49 | R13: 0 | S13: 1500
... A34: valeriejjohnson@gmail.com | B34: valerie | C34: johnson | D34: South Holland | E34: IL | F34: levitz furniture | G34: Campaign_8 | H34: Google Ads | I34: 2024-01-29 | J34: 100 | K34: 1159 | L34: 24 | M34: 2 | N34: 13.03 | O34: 133.86 | P34: 2.07 | Q34: 0.54 | R34: 6.52 | S34: 4500
A35: samkrb101@gmail.com | B35: sam | C35: kirby | D35: Goreville | E35: IL | F35: 0 | G35: Campaign_13 | H35: Google Ads | I35: 2024-01-24 | J35: 400 | K35: 788 | L35: 17 | M35: 0 | N35: 13.99 | O35: 0 | P35: 2.16 | Q35: 0.82 | R35: 0 | S35: 5417
A36: januaryh272@yahoo.com | B36: january | C36: harris | D36: Saint Louis | E36: MO | F36: gma paralegal services;llc | G36: Campaign_6 | H36: Google Ads | I36: 2024-01-11 | J36: 400 | K36: 1941 | L36: 85 | M36: 3 | N36: 40.6 | O36: 136.75 | P36: 4.38 | Q36: 0.48 | R36: 13.53 | S36: 1300
A37: valeriewalden@yahoo.com | B37: valerie | C37: walden | D37: Beaumont | E37: TX | F37: forth & towne | G37: Campaign_16 | H37: Google Ads | I37: 2024-01-08 | J37: 700 | K37: 676 | L37: 22 | M37: 1 | N37: 14.77 | O37: 49.55 | P37: 3.25 | Q37: 0.67 | R37: 14.77 | S37: 1500
A38: uearl51@yahoo.com | B38: earl | C38: underwood | D38: Navasota | E38: TX | F38: bj trucking | G38: Campaign_4 | H38: Google Ads | I38: 2024-01-13 | J38: 500 | K38: 1268 | L38: 50 | M38: 1 | N38: 34.57 | O38: 50.35 | P38: 3.94 | Q38: 0.69 | R38: 34.57 | S38: 2167
A39: jonesletique@gmail.com | B39: cathy | C39: jones | D39: Houston | E39: TX | F39: houstonisd | G39: Campaign_2 | H39: Google Ads | I39: 2024-01-08 | J39: 700 | K39: 541 | L39: 18 | M39: 0 | N39: 11.76 | O39: 0 | P39: 3.33 | Q39: 0.65 | R39: 0 | S39: 2708
A40: elmarquez@gmail.com | B40: eloise | C40: marquez | D40: Portland | E40: OR | F40: realty depot | G40: Campaign_17 | H40: Google Ads | I40: 2024-01-08 | J40: 100 | K40: 1818 | L40: 67 | M40: 0 | N40: 43.74 | O40: 0 | P40: 3.69 | Q40: 0.65 | R40: 0 | S40: 3250
A41: laboy783@yahoo.com | B41: eliseo | C41: duarte | D41: Dallas | E41: TX | F41: bumc | G41: Campaign_20 | H41: Google Ads | I41: 2024-01-28 | J41: 400 | K41: 2032 | L41: 90 | M41: 0 | N41: 74.64 | O41: 0 | P41: 4.43 | Q41: 0.83 | R41: 0 | S41: 4100
A42: bbluv4u2@yahoo.com | B42: marlin | C42: brown | D42: Concord | E42: NC | F42: china spring isd | G42: Campaign_19 | H42: Google Ads | I42: 2024-01-23 | J42: 300 | K42: 2373 | L42: 55 | M42: 0 | N42: 25.61 | O42: 0 | P42: 2.32 | Q42: 0.47 | R42: 0 | S42: 3400
A43: heruone2000@yahoo.com | B43: terrance | C43: merck | D43: Detroit | E43: MI | F43: embrenche | G43: Campaign_8 | H43: Google Ads | I43: 2024-01-17 | J43: 1000 | K43: 1148 | L43: 17 | M43: 1 | N43: 8.05 | O43: 70.32 | P43: 1.48 | Q43: 0.47 | R43: 8.05 | S43: 2498
A44: buffanged@yahoo.com | B44: angela | C44: buffington | D44: Nicholasville | E44: KY | F44: eden bishop | G44: Campaign_19 | H44: Google Ads | I44: 2024-01-15 | J44: 500 | K44: 2166 | L44: 39 | M44: 3 | N44: 20.6 | O44: 175.07 | P44: 1.8 | Q44: 0.53 | R44: 6.87 | S44: 2167
A45: rkarinagarzon@hotmail.com | B45: rosana | C45: lamoglia | D45: Naples | E45: FL | F45: pelicanbayfoundation | G45: Campaign_17 | H45: Google Ads | I45: 2024-01-10 | J45: 600 | K45: 1430 | L45: 61 | M45: 2 | N45: 45.15 | O45: 104.72 | P45: 4.27 | Q45: 0.74 | R45: 22.58 | S45: 2000
A46: ortizana85@gmail.com | B46: ana | C46: villanueva | D46: Arlington | E46: TX | F46: ats | G46: Campaign_11 | H46: Google Ads | I46: 2024-01-14 | J46: 1000 | K46: 2055 | L46: 85 | M46: 0 | N46: 64.77 | O46: 0 | P46: 4.14 | Q46: 0.76 | R46: 0 | S46: 3100
A47: revo6419@gmail.com | B47: david | C47: revolinski | D47: Fort Atkinson | E47: WI | F47: eaton | G47: Campaign_20 | H47: Google Ads | I47: 2024-01-20 | J47: 400 | K47: 1727 | L47: 26 | M47: 3 | N47: 16.67 | O47: 162.56 | P47: 1.51 | Q47: 0.64 | R47: 5.56 | S47: 1924
... A61: dtfrison05@yahoo.com | B61: dawntesha | C61: frison | D61: Tolleson | E61: AZ | F61: wells fargo | G61: Campaign_10 | H61: Google Ads | I61: 2024-01-28 | J61: 700 | K61: 850 | L61: 22 | M61: 0 | N61: 15.66 | O61: 0 | P61: 2.59 | Q61: 0.71 | R61: 0 | S61: 2708
A62: rgililland@live.com | B62: rebekah | C62: gililland | D62: Oklahoma City | E62: OK | F62: 0 | G62: Campaign_7 | H62: Google Ads | I62: 2024-01-03 | J62: 400 | K62: 834 | L62: 15 | M62: 0 | N62: 7.46 | O62: 0 | P62: 1.8 | Q62: 0.5 | R62: 0 | S62: 1733
A63: a30yroldfrog@aol.com | B63: angela | C63: stephens | D63: Lehigh Acres | E63: FL | F63: murphy usa | G63: Campaign_13 | H63: Google Ads | I63: 2024-01-28 | J63: 1000 | K63: 648 | L63: 26 | M63: 0 | N63: 16.05 | O63: 0 | P63: 4.01 | Q63: 0.62 | R63: 0 | S63: 2500
A64: aydinsmommy1221@live.com | B64: terina | C64: barlow | D64: Chicago | E64: IL | F64: tcf national bank illinois | G64: Campaign_13 | H64: Google Ads | I64: 2024-01-06 | J64: 100 | K64: 893 | L64: 15 | M64: 0 | N64: 7.26 | O64: 0 | P64: 1.68 | Q64: 0.48 | R64: 0 | S64: 3900
A65: tiffanylenae04@yahoo.com | B65: tiffany | C65: mock | D65: Ravenna | E65: NE | F65: cabelas | G65: Campaign_7 | H65: Google Ads | I65: 2024-01-12 | J65: 800 | K65: 1515 | L65: 33 | M65: 0 | N65: 18.21 | O65: 0 | P65: 2.18 | Q65: 0.55 | R65: 0 | S65: 2250
A66: christylnolen@abbey.bac.edu | B66: christy | C66: nolen | D66: Cramerton | E66: NC | F66: mcso | G66: Campaign_12 | H66: Google Ads | I66: 2024-01-23 | J66: 800 | K66: 1846 | L66: 41 | M66: 0 | N66: 32.59 | O66: 0 | P66: 2.22 | Q66: 0.79 | R66: 0 | S66: 4604
A67: lebpsc09@yahoo.com | B67: pam | C67: coston | D67: Charlotte | E67: NC | F67: branch banking and trust compa | G67: Campaign_4 | H67: Google Ads | I67: 2024-01-24 | J67: 100 | K67: 936 | L67: 18 | M67: 0 | N67: 9.31 | O67: 0 | P67: 1.92 | Q67: 0.52 | R67: 0 | S67: 4800
A68: crayfield65@gmail.com | B68: christina | C68: rayfield | D68: Houston | E68: TX | F68: central market | G68: Campaign_11 | H68: Google Ads | I68: 2024-01-22 | J68: 1000 | K68: 667 | L68: 17 | M68: 0 | N68: 7.61 | O68: 0 | P68: 2.55 | Q68: 0.45 | R68: 0 | S68: 2200
A69: samuel_brown84@yahoo.com | B69: brown | C69: sam | D69: Cleveland | E69: TX | F69: pitney bowes | G69: Campaign_6 | H69: Google Ads | I69: 2024-01-07 | J69: 200 | K69: 978 | L69: 40 | M69: 4 | N69: 22.01 | O69: 220 | P69: 4.09 | Q69: 0.55 | R69: 5.5 | S69: 2500
A70: hdw1865@yahoo.com | B70: howard | C70: webster | D70: Crewe | E70: VA | F70: mark dunning ind. | G70: Campaign_12 | H70: Google Ads | I70: 2024-01-03 | J70: 1000 | K70: 1825 | L70: 77 | M70: 0 | N70: 46.53 | O70: 0 | P70: 4.22 | Q70: 0.6 | R70: 0 | S70: 2000
A71: kidwellk1031@aol.com | B71: kim | C71: kidwell | D71: Kokomo | E71: IN | F71: compass | G71: Campaign_1 | H71: Google Ads | I71: 2024-01-08 | J71: 300 | K71: 1807 | L71: 46 | M71: 1 | N71: 31.07 | O71: 70.38 | P71: 2.55 | Q71: 0.68 | R71: 31.07 | S71: 3300
A72: jhockemeyer812@gmail.com | B72: jonathan | C72: hockemeyer | D72: Burleson | E72: TX | F72: bankston chevrolet | G72: Campaign_9 | H72: Google Ads | I72: 2024-01-30 | J72: 800 | K72: 2403 | L72: 57 | M72: 2 | N72: 47.38 | O72: 127.73 | P72: 2.37 | Q72: 0.83 | R72: 23.69 | S72: 4500
A73: deemurray91@gmail.com | B73: deanna | C73: murray | D73: Fayetteville | E73: NC | F73: deanna murray | G73: Campaign_18 | H73: Google Ads | I73: 2024-01-06 | J73: 100 | K73: 2212 | L73: 81 | M73: 7 | N73: 34.45 | O73: 519.26 | P73: 3.66 | Q73: 0.43 | R73: 4.92 | S73: 1699
...

Sheet raw_meta
A1: EMAIL | B1: firstname | C1: lastname | D1: city | E1: state | F1: employer | G1: campaign_name | H1: platform | I1: Date | J1: loan_amount.1 | K1: impressions | L1: clicks | M1: conversions | N1: cost | O1: revenue | P1: CTR | Q1: CPC | R1: CPA | S1: salary
A2: claudiaboyd2@yahoo.com | B2: claudia | C2: boyd | D2: Greenwood | E2: MS | F2: leflore county school district | G2: Campaign_18 | H2: Facebook Ads | I2: 2024-01-31 | J2: 400 | K2: 1688 | L2: 55 | M2: 0 | N2: 32.23 | O2: 0 | P2: 3.26 | Q2: 0.59 | R2: 0 | S2: 5958
A3: smrdar218@yahoo.com | B3: sadie | C3: royster | D3: Uniontown | E3: PA | F3: chs | G3: Campaign_7 | H3: Facebook Ads | I3: 2024-01-01 | J3: 700 | K3: 678 | L3: 18 | M3: 0 | N3: 8.62 | O3: 0 | P3: 2.65 | Q3: 0.48 | R3: 0 | S3: 3750
A4: jonesdarryl427@yahoo.com | B4: darryl | C4: jones | D4: Walnut Cove | E4: NC | F4: materials management | G4: Campaign_11 | H4: Facebook Ads | I4: 2024-01-22 | J4: 700 | K4: 1179 | L4: 42 | M4: 1 | N4: 21.11 | O4: 55.69 | P4: 3.56 | Q4: 0.5 | R4: 21.11 | S4: 4100
A5: telly1188@gmail.com | B5: shantel | C5: shantel | D5: Winston Salem | E5: NC | F5: twin city quarters | G5: Campaign_18 | H5: Facebook Ads | I5: 2024-01-04 | J5: 800 | K5: 1645 | L5: 56 | M5: 4 | N5: 40.74 | O5: 142.03 | P5: 3.4 | Q5: 0.73 | R5: 10.18 | S5: 3250
A6: bethahud@bellsouth.net | B6: mary | C6: hudson | D6: Knoxville | E6: TN | F6: knox county schools | G6: Campaign_6 | H6: Facebook Ads | I6: 2024-01-05 | J6: 500 | K6: 1315 | L6: 24 | M6: 0 | N6: 18.7 | O6: 0 | P6: 1.83 | Q6: 0.78 | R6: 0 | S6: 4900
A7: cnvarez85@gmail.com | B7: crystal | C7: nevarez | D7: Tallahassee | E7: FL | F7: south east eye specialist | G7: Campaign_17 | H7: Facebook Ads | I7: 2024-01-02 | J7: 300 | K7: 1165 | L7: 23 | M7: 2 | N7: 11.23 | O7: 115.62 | P7: 1.97 | Q7: 0.49 | R7: 5.62 | S7: 5000
A8: fanaticartrepreneur@yahoo.com | B8: dolllicia | C8: white | D8: Harrisburg | E8: PA | F8: department of auditor | G8: Campaign_7 | H8: Facebook Ads | I8: 2024-01-24 | J8: 200 | K8: 1248 | L8: 54 | M8: 1 | N8: 37.21 | O8: 45.12 | P8: 4.33 | Q8: 0.69 | R8: 37.21 | S8: 3700
A9: jmnaber@gmail.com | B9: jiries | C9: naber | D9: Canyon Countr | E9: CA | F9: in home supportive sercives | G9: Campaign_1 | H9: Facebook Ads | I9: 2024-01-03 | J9: 100 | K9: 2424 | L9: 86 | M9: 3 | N9: 54.01 | O9: 171.74 | P9: 3.55 | Q9: 0.63 | R9: 18 | S9: 3500
A10: fcb112@gmail.com | B10: frederick | C10: berry | D10: San Antonio | E10: TX | F10: woolf brothers | G10: Campaign_17 | H10: Facebook Ads | I10: 2024-01-07 | J10: 300 | K10: 2233 | L10: 81 | M10: 9 | N10: 67.58 | O10: 348.93 | P10: 3.63 | Q10: 0.83 | R10: 7.51 | S10: 2500
A11: lisawatson@optonline.net | B11: lisa | C11: watson | D11: Passaic | E11: NJ | F11: pnc bank new jersey | G11: Campaign_4 | H11: Facebook Ads | I11: 2024-01-15 | J11: 300 | K11: 2432 | L11: 39 | M11: 0 | N11: 16.2 | O11: 0 | P11: 1.6 | Q11: 0.42 | R11: 0 | S11: 1000
A12: lilchristian704@yahoo.com | B12: shamika | C12: hairston | D12: Houston | E12: TX | F12: fresenius | G12: Campaign_9 | H12: Facebook Ads | I12: 2024-01-31 | J12: 500 | K12: 1844 | L12: 72 | M12: 7 | N12: 29.5 | O12: 427.32 | P12: 3.9 | Q12: 0.41 | R12: 4.21 | S12: 1300
A13: jessdav19@gmail.com | B13: jessica | C13: davis | D13: Conroe | E13: TX | F13: tx dept of criminal justice | G13: Campaign_20 | H13: Facebook Ads | I13: 2024-01-25 | J13: 1000 | K13: 1364 | L13: 20 | M13: 0 | N13: 14.41 | O13: 0 | P13: 1.47 | Q13: 0.72 | R13: 0 | S13: 2334
... A361: chichismom29@hotmail.com | B361: dago | C361: villamil | D361: Hialeah | E361: FL | F361: asrc | G361: Campaign_1 | H361: Facebook Ads | I361: 2024-01-06 | J361: 200 | K361: 1675 | L361: 27 | M361: 0 | N361: 17.61 | O361: 0 | P361: 1.61 | Q361: 0.65 | R361: 0 | S361: 4500
A362: gothamsknights@hotmail.com | B362: aaron | C362: moser | D362: Maricopa | E362: AZ | F362: 0 | G362: Campaign_14 | H362: Facebook Ads | I362: 2024-01-08 | J362: 100 | K362: 551 | L362: 21 | M362: 0 | N362: 13.92 | O362: 0 | P362: 3.81 | Q362: 0.66 | R362: 0 | S362: 2750
A363: teresha0824@yahoo.com | B363: teresha | C363: cooper | D363: Houston | E363: TX | F363: at and t | G363: Campaign_18 | H363: Facebook Ads | I363: 2024-01-30 | J363: 400 | K363: 1279 | L363: 53 | M363: 1 | N363: 25.33 | O363: 73.65 | P363: 4.14 | Q363: 0.48 | R363: 25.33 | S363: 2250
A364: shyraaaa@hotmail.com | B364: latoya | C364: paige | D364: Tuscaloosa | E364: AL | F364: self | G364: Campaign_9 | H364: Facebook Ads | I364: 2024-01-23 | J364: 700 | K364: 2203 | L364: 73 | M364: 0 | N364: 33.56 | O364: 0 | P364: 3.31 | Q364: 0.46 | R364: 0 | S364: 2200
A365: usmarinemom46@yahoo.com | B365: lori | C365: martin | D365: Worcester | E365: MA | F365: durham school services | G365: Campaign_15 | H365: Facebook Ads | I365: 2024-01-15 | J365: 400 | K365: 2019 | L365: 80 | M365: 0 | N365: 37.32 | O365: 0 | P365: 3.96 | Q365: 0.47 | R365: 0 | S365: 2000
A366: bnjmnwhtnr634@gmail.com | B366: benjamin | C366: whitener | D366: Athens | E366: GA | F366: nibco | G366: Campaign_5 | H366: Facebook Ads | I366: 2024-01-19 | J366: 500 | K366: 1275 | L366: 53 | M366: 2 | N366: 33.71 | O366: 80.15 | P366: 4.16 | Q366: 0.64 | R366: 16.86 | S366: 4800
A367: robert212315@gmail.com | B367: wayne | C367: kitten | D367: Chicago | E367: IL | F367: midtown toyota | G367: Campaign_16 | H367: Facebook Ads | I367: 2024-01-26 | J367: 800 | K367: 1880 | L367: 31 | M367: 3 | N367: 25.88 | O367: 159.56 | P367: 1.65 | Q367: 0.83 | R367: 8.63 | S367: 4100
A368: lisa_dawn_72@yahoo.com | B368: lisa | C368: simons | D368: Montgomery | E368: TX | F368: k9kuts | G368: Campaign_17 | H368: Facebook Ads | I368: 2024-01-21 | J368: 100 | K368: 1400 | L368: 54 | M368: 1 | N368: 38.63 | O368: 47.32 | P368: 3.86 | Q368: 0.72 | R368: 38.63 | S368: 2700
A369: williamlacayo@hotmail.com | B369: william | C369: lacayo | D369: Miami | E369: FL | F369: larkin community hospital | G369: Campaign_4 | H369: Facebook Ads | I369: 2024-01-18 | J369: 800 | K369: 1380 | L369: 34 | M369: 0 | N369: 22.45 | O369: 0 | P369: 2.46 | Q369: 0.66 | R369: 0 | S369: 4500
A370: andreasand27@hotmail.com | B370: andrea | C370: sanders | D370: Chicago | E370: IL | F370: uas properties | G370: Campaign_18 | H370: Facebook Ads | I370: 2024-01-25 | J370: 200 | K370: 2497 | L370: 64 | M370: 0 | N370: 49.9 | O370: 0 | P370: 2.56 | Q370: 0.78 | R370: 0 | S370: 2400
A371: kyla.steenson@gmail.com | B371: kyla | C371: steenson | D371: Kanopolis | E371: KS | F371: casey's general story | G371: Campaign_13 | H371: Facebook Ads | I371: 2024-01-25 | J371: 500 | K371: 1417 | L371: 46 | M371: 4 | N371: 23.59 | O371: 185.32 | P371: 3.25 | Q371: 0.51 | R371: 5.9 | S371: 1560
A372: jr.correa176@gmail.com | B372: gumercindo | C372: correa | D372: Dimmitt | E372: TX | F372: texas tech university | G372: Campaign_4 | H372: Facebook Ads | I372: 2024-01-13 | J372: 600 | K372: 1008 | L372: 17 | M372: 1 | N372: 13.82 | O372: 53.69 | P372: 1.69 | Q372: 0.81 | R372: 13.82 | S372: 2000
A373: racmckin@yahoo.com | B373: racheal | C373: mckinnon | D373: Rhineland | E373: MO | F373: parker hannifin sporlan | G373: Campaign_11 | H373: Facebook Ads | I373: 2024-01-12 | J373: 200 | K373: 813 | L373: 19 | M373: 2 | N373: 12.53 | O373: 149.12 | P373: 2.34 | Q373: 0.66 | R373: 6.26 | S373: 1499
A374: cleora_9@yahoo.com | B374: brockbank | C374: cleora | D374: Ballwin | E374: MO | F374: burger king | G374: Campaign_19 | H374: Facebook Ads | I374: 2024-01-13 | J374: 100 | K374: 1740 | L374: 28 | M374: 0 | N374: 17.9 | O374: 0 | P374: 1.61 | Q374: 0.64 | R374: 0 | S374: 2166
... A446: ventwan21@gmail.com | B446: napoleon | C446: hall | D446: Atlanta | E446: GA | F446: e transform | G446: Campaign_14 | H446: Facebook Ads | I446: 2024-01-04 | J446: 800 | K446: 734 | L446: 13 | M446: 0 | N446: 6.06 | O446: 0 | P446: 1.77 | Q446: 0.47 | R446: 0 | S446: 4333
A447: sabrina.jenkins1@yahoo.com | B447: willie | C447: jenkins | D447: Auburndale | E447: FL | F447: 0 | G447: Campaign_8 | H447: Facebook Ads | I447: 2024-01-30 | J447: 100 | K447: 612 | L447: 18 | M447: 0 | N447: 11.1 | O447: 0 | P447: 2.94 | Q447: 0.62 | R447: 0 | S447: 2750
A448: amazingjana@yahoo.com | B448: january | C448: jurado | D448: Daly City | E448: CA | F448: ucsf medical center | G448: Campaign_3 | H448: Facebook Ads | I448: 2024-01-24 | J448: 1000 | K448: 2415 | L448: 98 | M448: 3 | N448: 61.05 | O448: 136.03 | P448: 4.06 | Q448: 0.62 | R448: 20.35 | S448: 1196
A449: huiihochen@yahoo.com | B449: xiuyan | C449: ge | D449: Monterey Park | E449: CA | F449: wu construction co | G449: Campaign_10 | H449: Facebook Ads | I449: 2024-01-23 | J449: 1000 | K449: 1004 | L449: 22 | M449: 2 | N449: 13.07 | O449: 135.32 | P449: 2.19 | Q449: 0.59 | R449: 6.54 | S449: 1864
A450: jramosdirect@yahoo.com | B450: john | C450: ramos | D450: Provo | E450: UT | F450: brownstrauss steel | G450: Campaign_17 | H450: Facebook Ads | I450: 2024-01-20 | J450: 400 | K450: 576 | L450: 12 | M450: 0 | N450: 7.35 | O450: 0 | P450: 2.08 | Q450: 0.61 | R450: 0 | S450: 1600
A451: nicole_espinoza1983@yahoo.com | B451: ronald | C451: simmons | D451: Hamilton | E451: TX | F451: flowers construction/infastrux | G451: Campaign_9 | H451: Facebook Ads | I451: 2024-01-27 | J451: 500 | K451: 1551 | L451: 68 | M451: 2 | N451: 28.87 | O451: 84.5 | P451: 4.38 | Q451: 0.42 | R451: 14.44 | S451: 3160
A452: shimia81@msn.com | B452: shimia | C452: forch | D452: Tacoma | E452: WA | F452: target | G452: Campaign_3 | H452: Facebook Ads | I452: 2024-01-21 | J452: 500 | K452: 734 | L452: 31 | M452: 2 | N452: 14.52 | O452: 80.52 | P452: 4.22 | Q452: 0.47 | R452: 7.26 | S452: 4200
A453: ms.terry7338@yahoo.com | B453: terry | C453: morgan | D453: Franklinton | E453: NC | F453: cooke health care | G453: Campaign_3 | H453: Facebook Ads | I453: 2024-01-25 | J453: 200 | K453: 1505 | L453: 65 | M453: 0 | N453: 50.69 | O453: 0 | P453: 4.32 | Q453: 0.78 | R453: 0 | S453: 1400
A454: sxynurse32@gmail.com | B454: kenneth | C454: smith | D454: Sandusky | E454: OH | F454: ohio veterans home | G454: Campaign_20 | H454: Facebook Ads | I454: 2024-01-24 | J454: 200 | K454: 1909 | L454: 42 | M454: 1 | N454: 32.51 | O454: 44.62 | P454: 2.2 | Q454: 0.77 | R454: 32.51 | S454: 1100
A455: rigmechanic2000@yahoo.com | B455: humberto | C455: botello | D455: Corpus Christ | E455: TX | F455: holt cat | G455: Campaign_20 | H455: Facebook Ads | I455: 2024-01-07 | J455: 100 | K455: 1807 | L455: 36 | M455: 0 | N455: 22.02 | O455: 0 | P455: 1.99 | Q455: 0.61 | R455: 0 | S455: 3250
A456: baybaynealy@yahoo.com | B456: gwenda | C456: nealy | D456: High Point | E456: NC | F456: kmart | G456: Campaign_12 | H456: Facebook Ads | I456: 2024-01-12 | J456: 800 | K456: 1902 | L456: 61 | M456: 0 | N456: 40.23 | O456: 0 | P456: 3.21 | Q456: 0.66 | R456: 0 | S456: 1500
A457: matilda_sanchez@hotmail.com | B457: matilda | C457: sanchez | D457: Fullerton | E457: CA | F457: homdepot | G457: Campaign_6 | H457: Facebook Ads | I457: 2024-01-26 | J457: 300 | K457: 1037 | L457: 27 | M457: 0 | N457: 14.37 | O457: 0 | P457: 2.6 | Q457: 0.53 | R457: 0 | S457: 2600
A458: adknott13@msn.com | B458: april | C458: emmel | D458: Reading | E458: PA | F458: pervading health system | G458: Campaign_3 | H458: Facebook Ads | I458: 2024-01-22 | J458: 1000 | K458: 1626 | L458: 46 | M458: 1 | N458: 21.46 | O458: 41.13 | P458: 2.83 | Q458: 0.47 | R458: 21.46 | S458: 3750
...

Sheet raw_tiktok
A1: EMAIL | B1: firstname | C1: lastname | D1: city | E1: state | F1: employer | G1: campaign_name | H1: platform | I1: Date | J1: loan_amount.1 | K1: impressions | L1: clicks | M1: conversions | N1: cost | O1: revenue | P1: CTR | Q1: CPC | R1: CPA | S1: salary
A2: ddarmahn@yahoo.com | B2: darmahn | C2: dixon | D2: Oakland | E2: CA | F2: state of california | G2: Campaign_9 | H2: TikTok Ads | I2: 2024-01-29 | J2: 500 | K2: 815 | L2: 33 | M2: 0 | N2: 26.72 | O2: 0 | P2: 4.05 | Q2: 0.81 | R2: 0 | S2: 4800
A3: anica79@yahoo.com | B3: candice | C3: george | D3: Seffner | E3: FL | F3: security finance | G3: Campaign_1 | H3: TikTok Ads | I3: 2024-01-30 | J3: 300 | K3: 1053 | L3: 29 | M3: 0 | N3: 15.22 | O3: 0 | P3: 2.75 | Q3: 0.52 | R3: 0 | S3: 1733
A4: aliclift.ac@gmail.com | B4: alexandria | C4: clift | D4: San Antonio | E4: TX | F4: united marketing group | G4: Campaign_3 | H4: TikTok Ads | I4: 2024-01-26 | J4: 400 | K4: 1557 | L4: 63 | M4: 2 | N4: 51.76 | O4: 82.43 | P4: 4.05 | Q4: 0.82 | R4: 25.88 | S4: 1800
A5: davidvonalst@yahoo.com | B5: barbara | C5: vonalst | D5: Pahrump | E5: NV | F5: self employed | G5: Campaign_8 | H5: TikTok Ads | I5: 2024-01-25 | J5: 800 | K5: 832 | L5: 32 | M5: 1 | N5: 22.24 | O5: 73.82 | P5: 3.85 | Q5: 0.7 | R5: 22.24 | S5: 1000
A6: arcuricraig@gmail.com | B6: craig | C6: arcuri | D6: Susquehanna | E6: PA | F6: penn star bank | G6: Campaign_16 | H6: TikTok Ads | I6: 2024-01-15 | J6: 600 | K6: 627 | L6: 10 | M6: 0 | N6: 8.08 | O6: 0 | P6: 1.59 | Q6: 0.81 | R6: 0 | S6: 6461
A7: hyarpih98@gmail.com | B7: ayarpi | C7: sogomonyan | D7: North Hollywo | E7: CA | F7: hpmc | G7: Campaign_7 | H7: TikTok Ads | I7: 2024-01-26 | J7: 200 | K7: 919 | L7: 23 | M7: 2 | N7: 16.29 | O7: 149.55 | P7: 2.5 | Q7: 0.71 | R7: 8.14 | S7: 5666
A8: kenishatquick@hotmail.com | B8: kenisha | C8: quick | D8: West Point | E8: GA | F8: soundtrack | G8: Campaign_17 | H8: TikTok Ads | I8: 2024-01-23 | J8: 800 | K8: 1099 | L8: 28 | M8: 1 | N8: 13.24 | O8: 46.5 | P8: 2.55 | Q8: 0.47 | R8: 13.24 | S8: 2250
A9: fields1900@gmail.com | B9: nena | C9: fields | D9: Norristown | E9: PA | F9: legal aid of se pa | G9: Campaign_6 | H9: TikTok Ads | I9: 2024-01-15 | J9: 500 | K9: 2129 | L9: 50 | M9: 2 | N9: 34.28 | O9: 70.93 | P9: 2.35 | Q9: 0.69 | R9: 17.14 | S9: 3900
A10: hectorcolonarias@yahoo.com | B10: hector | C10: colon | D10: caguas | E10: PA | F10: gilster marylee | G10: Campaign_10 | H10: TikTok Ads | I10: 2024-01-09 | J10: 100 | K10: 2165 | L10: 49 | M10: 5 | N10: 23.79 | O10: 195.93 | P10: 2.26 | Q10: 0.49 | R10: 4.76 | S10: 3750
A11: helenjdavis@hotmail.com | B11: helen | C11: davis | D11: Harrisburg | E11: PA | F11: star merchant services | G11: Campaign_14 | H11: TikTok Ads | I11: 2024-01-22 | J11: 600 | K11: 895 | L11: 23 | M11: 0 | N11: 18.4 | O11: 0 | P11: 2.57 | Q11: 0.8 | R11: 0 | S11: 1463
A12: jeannieandtrudy@hotmail.com | B12: trudy | C12: givens | D12: Porterville | E12: CA | F12: 0 | G12: Campaign_7 | H12: TikTok Ads | I12: 2024-01-13 | J12: 1000 | K12: 1495 | L12: 66 | M12: 6 | N12: 46.54 | O12: 347.09 | P12: 4.41 | Q12: 0.71 | R12: 7.76 | S12: 5000
A13: krtjjjj@yahoo.com | B13: terri | C13: hilton | D13: Philadelphia | E13: PA | F13: disabled | G13: Campaign_13 | H13: TikTok Ads | I13: 2024-01-25 | J13: 700 | K13: 2347 | L13: 105 | M13: 10 | N13: 77.52 | O13: 356.18 | P13: 4.47 | Q13: 0.74 | R13: 7.75 | S13: 2078
